/uscms/home/joyzhou/nobackup/newcoffea/lib/python3.9/site-packages/distributed/node.py:182: UserWarning: Port 8787 is already in use.
Perhaps you already have a cluster running?
Hosting the HTTP server on port 44274 instead
  warnings.warn(
/uscms/home/joyzhou/nobackup/newcoffea/lib/python3.9/site-packages/distributed/node.py:182: UserWarning: Port 8787 is already in use.
Perhaps you already have a cluster running?
Hosting the HTTP server on port 39591 instead
  warnings.warn(
2024-02-05 16:27:26,152 - distributed.nanny - ERROR - Failed to start process
Traceback (most recent call last):
  File "/uscms/home/joyzhou/nobackup/newcoffea/lib/python3.9/site-packages/distributed/nanny.py", line 455, in instantiate
    result = await self.process.start()
  File "/uscms/home/joyzhou/nobackup/newcoffea/lib/python3.9/site-packages/distributed/nanny.py", line 755, in start
    await self.process.start()
  File "/uscms/home/joyzhou/nobackup/newcoffea/lib/python3.9/site-packages/distributed/process.py", line 55, in _call_and_set_future
    res = func(*args, **kwargs)
  File "/uscms/home/joyzhou/nobackup/newcoffea/lib/python3.9/site-packages/distributed/process.py", line 215, in _start
    process.start()
  File "/cvmfs/sft.cern.ch/lcg/releases/LCG_104swan/Python/3.9.12/x86_64-centos7-gcc11-opt/lib/python3.9/multiprocessing/process.py", line 121, in start
    self._popen = self._Popen(self)
  File "/cvmfs/sft.cern.ch/lcg/releases/LCG_104swan/Python/3.9.12/x86_64-centos7-gcc11-opt/lib/python3.9/multiprocessing/context.py", line 284, in _Popen
    return Popen(process_obj)
  File "/cvmfs/sft.cern.ch/lcg/releases/LCG_104swan/Python/3.9.12/x86_64-centos7-gcc11-opt/lib/python3.9/multiprocessing/popen_spawn_posix.py", line 32, in __init__
    super().__init__(process_obj)
  File "/cvmfs/sft.cern.ch/lcg/releases/LCG_104swan/Python/3.9.12/x86_64-centos7-gcc11-opt/lib/python3.9/multiprocessing/popen_fork.py", line 19, in __init__
    self._launch(process_obj)
  File "/cvmfs/sft.cern.ch/lcg/releases/LCG_104swan/Python/3.9.12/x86_64-centos7-gcc11-opt/lib/python3.9/multiprocessing/popen_spawn_posix.py", line 42, in _launch
    prep_data = spawn.get_preparation_data(process_obj._name)
  File "/cvmfs/sft.cern.ch/lcg/releases/LCG_104swan/Python/3.9.12/x86_64-centos7-gcc11-opt/lib/python3.9/multiprocessing/spawn.py", line 154, in get_preparation_data
    _check_not_importing_main()
  File "/cvmfs/sft.cern.ch/lcg/releases/LCG_104swan/Python/3.9.12/x86_64-centos7-gcc11-opt/lib/python3.9/multiprocessing/spawn.py", line 134, in _check_not_importing_main
    raise RuntimeError('''
RuntimeError: 
        An attempt has been made to start a new process before the
        current process has finished its bootstrapping phase.

        This probably means that you are not using fork to start your
        child processes and you have forgotten to use the proper idiom
        in the main module:

            if __name__ == '__main__':
                freeze_support()
                ...

        The "freeze_support()" line can be omitted if the program
        is not going to be frozen to produce an executable.
2024-02-05 16:27:26,152 - distributed.nanny - ERROR - Failed to start process
Traceback (most recent call last):
  File "/uscms/home/joyzhou/nobackup/newcoffea/lib/python3.9/site-packages/distributed/nanny.py", line 455, in instantiate
    result = await self.process.start()
  File "/uscms/home/joyzhou/nobackup/newcoffea/lib/python3.9/site-packages/distributed/nanny.py", line 755, in start
    await self.process.start()
  File "/uscms/home/joyzhou/nobackup/newcoffea/lib/python3.9/site-packages/distributed/process.py", line 55, in _call_and_set_future
    res = func(*args, **kwargs)
  File "/uscms/home/joyzhou/nobackup/newcoffea/lib/python3.9/site-packages/distributed/process.py", line 215, in _start
    process.start()
  File "/cvmfs/sft.cern.ch/lcg/releases/LCG_104swan/Python/3.9.12/x86_64-centos7-gcc11-opt/lib/python3.9/multiprocessing/process.py", line 121, in start
    self._popen = self._Popen(self)
  File "/cvmfs/sft.cern.ch/lcg/releases/LCG_104swan/Python/3.9.12/x86_64-centos7-gcc11-opt/lib/python3.9/multiprocessing/context.py", line 284, in _Popen
    return Popen(process_obj)
  File "/cvmfs/sft.cern.ch/lcg/releases/LCG_104swan/Python/3.9.12/x86_64-centos7-gcc11-opt/lib/python3.9/multiprocessing/popen_spawn_posix.py", line 32, in __init__
    super().__init__(process_obj)
  File "/cvmfs/sft.cern.ch/lcg/releases/LCG_104swan/Python/3.9.12/x86_64-centos7-gcc11-opt/lib/python3.9/multiprocessing/popen_fork.py", line 19, in __init__
    self._launch(process_obj)
  File "/cvmfs/sft.cern.ch/lcg/releases/LCG_104swan/Python/3.9.12/x86_64-centos7-gcc11-opt/lib/python3.9/multiprocessing/popen_spawn_posix.py", line 42, in _launch
    prep_data = spawn.get_preparation_data(process_obj._name)
  File "/cvmfs/sft.cern.ch/lcg/releases/LCG_104swan/Python/3.9.12/x86_64-centos7-gcc11-opt/lib/python3.9/multiprocessing/spawn.py", line 154, in get_preparation_data
    _check_not_importing_main()
  File "/cvmfs/sft.cern.ch/lcg/releases/LCG_104swan/Python/3.9.12/x86_64-centos7-gcc11-opt/lib/python3.9/multiprocessing/spawn.py", line 134, in _check_not_importing_main
    raise RuntimeError('''
RuntimeError: 
        An attempt has been made to start a new process before the
        current process has finished its bootstrapping phase.

        This probably means that you are not using fork to start your
        child processes and you have forgotten to use the proper idiom
        in the main module:

            if __name__ == '__main__':
                freeze_support()
                ...

        The "freeze_support()" line can be omitted if the program
        is not going to be frozen to produce an executable.
2024-02-05 16:27:26,613 - distributed.nanny - ERROR - Failed to start process
Traceback (most recent call last):
  File "/uscms/home/joyzhou/nobackup/newcoffea/lib/python3.9/site-packages/distributed/nanny.py", line 455, in instantiate
    result = await self.process.start()
  File "/uscms/home/joyzhou/nobackup/newcoffea/lib/python3.9/site-packages/distributed/nanny.py", line 755, in start
    await self.process.start()
  File "/uscms/home/joyzhou/nobackup/newcoffea/lib/python3.9/site-packages/distributed/process.py", line 55, in _call_and_set_future
    res = func(*args, **kwargs)
  File "/uscms/home/joyzhou/nobackup/newcoffea/lib/python3.9/site-packages/distributed/process.py", line 215, in _start
    process.start()
  File "/cvmfs/sft.cern.ch/lcg/releases/LCG_104swan/Python/3.9.12/x86_64-centos7-gcc11-opt/lib/python3.9/multiprocessing/process.py", line 121, in start
    self._popen = self._Popen(self)
  File "/cvmfs/sft.cern.ch/lcg/releases/LCG_104swan/Python/3.9.12/x86_64-centos7-gcc11-opt/lib/python3.9/multiprocessing/context.py", line 284, in _Popen
    return Popen(process_obj)
  File "/cvmfs/sft.cern.ch/lcg/releases/LCG_104swan/Python/3.9.12/x86_64-centos7-gcc11-opt/lib/python3.9/multiprocessing/popen_spawn_posix.py", line 32, in __init__
    super().__init__(process_obj)
  File "/cvmfs/sft.cern.ch/lcg/releases/LCG_104swan/Python/3.9.12/x86_64-centos7-gcc11-opt/lib/python3.9/multiprocessing/popen_fork.py", line 19, in __init__
    self._launch(process_obj)
  File "/cvmfs/sft.cern.ch/lcg/releases/LCG_104swan/Python/3.9.12/x86_64-centos7-gcc11-opt/lib/python3.9/multiprocessing/popen_spawn_posix.py", line 42, in _launch
    prep_data = spawn.get_preparation_data(process_obj._name)
  File "/cvmfs/sft.cern.ch/lcg/releases/LCG_104swan/Python/3.9.12/x86_64-centos7-gcc11-opt/lib/python3.9/multiprocessing/spawn.py", line 154, in get_preparation_data
    _check_not_importing_main()
  File "/cvmfs/sft.cern.ch/lcg/releases/LCG_104swan/Python/3.9.12/x86_64-centos7-gcc11-opt/lib/python3.9/multiprocessing/spawn.py", line 134, in _check_not_importing_main
    raise RuntimeError('''
RuntimeError: 
        An attempt has been made to start a new process before the
        current process has finished its bootstrapping phase.

        This probably means that you are not using fork to start your
        child processes and you have forgotten to use the proper idiom
        in the main module:

            if __name__ == '__main__':
                freeze_support()
                ...

        The "freeze_support()" line can be omitted if the program
        is not going to be frozen to produce an executable.
2024-02-05 16:27:26,613 - distributed.nanny - ERROR - Failed to start process
Traceback (most recent call last):
  File "/uscms/home/joyzhou/nobackup/newcoffea/lib/python3.9/site-packages/distributed/nanny.py", line 455, in instantiate
    result = await self.process.start()
  File "/uscms/home/joyzhou/nobackup/newcoffea/lib/python3.9/site-packages/distributed/nanny.py", line 755, in start
    await self.process.start()
  File "/uscms/home/joyzhou/nobackup/newcoffea/lib/python3.9/site-packages/distributed/process.py", line 55, in _call_and_set_future
    res = func(*args, **kwargs)
  File "/uscms/home/joyzhou/nobackup/newcoffea/lib/python3.9/site-packages/distributed/process.py", line 215, in _start
    process.start()
  File "/cvmfs/sft.cern.ch/lcg/releases/LCG_104swan/Python/3.9.12/x86_64-centos7-gcc11-opt/lib/python3.9/multiprocessing/process.py", line 121, in start
    self._popen = self._Popen(self)
  File "/cvmfs/sft.cern.ch/lcg/releases/LCG_104swan/Python/3.9.12/x86_64-centos7-gcc11-opt/lib/python3.9/multiprocessing/context.py", line 284, in _Popen
    return Popen(process_obj)
  File "/cvmfs/sft.cern.ch/lcg/releases/LCG_104swan/Python/3.9.12/x86_64-centos7-gcc11-opt/lib/python3.9/multiprocessing/popen_spawn_posix.py", line 32, in __init__
    super().__init__(process_obj)
  File "/cvmfs/sft.cern.ch/lcg/releases/LCG_104swan/Python/3.9.12/x86_64-centos7-gcc11-opt/lib/python3.9/multiprocessing/popen_fork.py", line 19, in __init__
    self._launch(process_obj)
  File "/cvmfs/sft.cern.ch/lcg/releases/LCG_104swan/Python/3.9.12/x86_64-centos7-gcc11-opt/lib/python3.9/multiprocessing/popen_spawn_posix.py", line 42, in _launch
    prep_data = spawn.get_preparation_data(process_obj._name)
  File "/cvmfs/sft.cern.ch/lcg/releases/LCG_104swan/Python/3.9.12/x86_64-centos7-gcc11-opt/lib/python3.9/multiprocessing/spawn.py", line 154, in get_preparation_data
    _check_not_importing_main()
  File "/cvmfs/sft.cern.ch/lcg/releases/LCG_104swan/Python/3.9.12/x86_64-centos7-gcc11-opt/lib/python3.9/multiprocessing/spawn.py", line 134, in _check_not_importing_main
    raise RuntimeError('''
RuntimeError: 
        An attempt has been made to start a new process before the
        current process has finished its bootstrapping phase.

        This probably means that you are not using fork to start your
        child processes and you have forgotten to use the proper idiom
        in the main module:

            if __name__ == '__main__':
                freeze_support()
                ...

        The "freeze_support()" line can be omitted if the program
        is not going to be frozen to produce an executable.
